Workbook

Sheet Cover
A1: Company Name | B1: Vinati Organics limited
A2: Stock Exchange | B2: NSE/ BSE
A3: Ticker | B3: VINATIORGA
A4: Model Type | B4: 3 Statement financial model + DCF valuation
A5: Currency | B5: INR (₹ Crores)
A6: Fiscal Year End | B6: 46112
A7: Historical Data | B7: FY2020 – FY2024
A8: Projection Period | B8: FY2025E – FY2027E
A9: Model Built By | B9: Yakuta Ali
A10: Date | B10: 46143
A11: Data Sources | B11: BSE Annual Reports, Screener.in

Sheet Raw Data
A1: Vinati Organics raw data | H1: COLOR CODING LEGEND
A2: Particulars | B2: FY2020 | C2: FY2021 | D2: FY2022 | E2: FY2023 | F2: FY2024 | G2: FY2025 | H2: Color | I2: Meaning
A3: INCOME | H3: Blue fill | I3: Hard coded input (number typed manually
A4: Revenue from operations | B4: 1028.87 | C4: 954.26 | D4: 1615.51 | E4: 2072.7 | F4: 1900 | G4: 2248.1 | H4: Green fill | I4: Formula Cells( calculated by Excel)
A5: Other income | B5: 44.99 | C5: 25.86 | D5: 60.96 | E5: 52.4 | F5: 38.8 | G5: 44.29 | H5: Yellow fill | I5: Assumption (Inputs in Assumptions tab)
A6: TOTAL INCOME | B6: =B4+B5 -> 1073.86 | C6: =C4+C5 -> 980.12 | D6: =D4+D5 -> 1676.47 | E6: 2125.2 | F6: 1938.8 | G6: =G4+G5 -> 2292.39 | H6: Purple fill | I6: Linked from another sheet (pull data across sheets)
A8: EXPENSES
A9: Cost of Materials Consumed | E9: 1077.9 | F9: 1010.2 | G9: 1182.29
A10: Purchase of Stock in Trade | E10: 0.6 | F10: 0 | G10: 0
A11: Changes in Inventories | E11: -4 | F11: 1.1 | G11: 14.08
A12: Employee Benefits Expense | E12: 99.6 | F12: 118.9 | G12: 137.99
A13: Finance Costs | B13: 2.04 | C13: 0.95 | D13: 1.65 | E13: 1.4 | F13: 3.6 | G13: 0.52
A14: Depreciation and Amortisation | B14: 33.16 | C14: 42.91 | D14: 45.49 | E14: 59 | F14: 72.8 | G14: 80.75
A15: Other Expenses | E15: 327.4 | F15: 299.6 | G15: 328.53
A16: TOTAL EXPENSES | B16: =SUM(B9,B10,B11,B12,B13,B14,B15) -> 35.2 | C16: =SUM(C9,C10,C11,C12,C13,C14,C15) -> 43.86 | D16: =SUM(D9,D10,D11,D12,D13,D14,D15) -> 47.14 | E16: 1562 | F16: 1506.3 | G16: =SUM(G9:G15) -> 1744.16
A17: Profit Before Tax | B17: =B6-B16 -> 1038.66 | C17: =C6-C16 -> 936.26 | D17: =D6-D16 -> 1629.33 | E17: =E6-E16 -> 563.2 | F17: =F6-F16 -> 432.5 | G17: =G6-G16 -> 548.23
A18: Tax Expense | B18: 90.84 | C18: 65.91 | D18: 102.63 | E18: 144 | F18: 109.1 | G18: 133
A19: Net Profit (PAT) | B19: =B17-B18 -> 947.82 | C19: =C17-C18 -> 870.35 | D19: =D17-D18 -> 1526.7 | E19: =E17-E18 -> 419.2 | F19: =F17-F18 -> 323.4 | G19: =G17-G18 -> 415.23
A21: KEY METRICS
A22: EBITDA | B22: =SUM(B17,B13,B14) -> 1073.86 | C22: =SUM(C17,C13,C14) -> 980.12 | D22: =SUM(D17,D13,D14) -> 1676.47 | E22: =SUM(E17,E13,E14) -> 623.6 | F22: =SUM(F17,F13,F14) -> 508.9 | G22: =G17+G13+G14 -> 629.5
A23: EBITDA Margin % | B23: =ROUND(B22/B4*100,1) -> 104.4 | C23: =ROUND(C22/C4*100,1) -> 102.7 | D23: =ROUND(D22/D4*100,1) -> 103.8 | E23: =ROUND(E22/E4*100,1) -> 30.1 | F23: =ROUND(F22/F4*100,1) -> 26.8 | G23: =ROUND(G22/G4*100,1) -> 28
A24: Net Profit Margin % | B24: =ROUND(B19/B4*100,1) -> 92.1 | C24: =ROUND(C19/C4*100,1) -> 91.2 | D24: =ROUND(D19/D4*100,1) -> 94.5 | E24: =ROUND(E19/E4*100,1) -> 20.2 | F24: =ROUND(F19/F4*100,1) -> 17 | G24: =ROUND(G19/G4*100,1) -> 18.5
A25: EPS - Basic | B25: 32.47 | C25: 26.2 | D25: 33.72 | E25: 40.43 | F25: 31.2 | G25: 40.05
A26: Revenue Growth % | C26: =ROUND((C4-B4)/C4*100,1) -> -7.8 | D26: =ROUND((D4-C4)/D4*100,1) -> 40.9 | E26: =ROUND((E4-D4)/E4*100,1) -> 22.1 | F26: =ROUND((F4-E4)/F4*100,1) -> -9.1 | G26: =(G4-F4)/F4*100 -> 18.321053

Sheet Assumption 
K2: Color | L2: Meaning
K3: Blue fill | L3: Hard coded input (number typed manually
K4: Green fill | L4: Formula Cells( calculated by Excel)
K5: Yellow fill | L5: Assumption (Inputs in Assumptions tab)
K6: Purple fill | L6: Linked from another sheet (pull data across sheets)
A8: Revenue Growth Assumption Rationale
A10: Vinati Organics' revenue is projected to grow at 12–15% in FY2025E and FY2026E, moderating to 10–12% in FY2027E. The near-term recovery is driven by normalisation of the global destocking cycle and the beginning of a restocking phase across key end-use industries. Domestic demand is expected to accelerate supported by India's position as the world's fastest-growing major economy, increased government spending on specialty chemical infrastructure under the PCPIR policy, and the Viksit Bharat initiative. Globally, the China Plus One sourcing strategy is redirecting chemical procurement toward Indian manufacturers, directly benefiting Vinati as the world's largest producer of IBB and ATBS. Long-term structural growth is underpinned by rising demand in water treatment, clean energy applications, and increasing per capita consumption in India.
A12: ASSUMPTION HEADER | B12: FY2026E | C12: FY2027E | D12: FY2028E
A13: Revenue Growth % | B13: 0.12 | C13: 0.1 | D13: 0.1
A14: Other Income (₹ Cr) | B14: 46 | C14: 48 | D14: 50
A15: Material Cost % of Revenue | B15: 0.52 | C15: 0.52 | D15: 0.51
A16: Employee Cost % of Revenue | B16: 0.062 | C16: 0.065 | D16: 0.065
A17: Finance Costs (₹ Cr) | B17: 2 | C17: 2 | D17: 2
A18: Depreciation (₹ Cr) | B18: 95 | C18: 105 | D18: 112
A19: Other Expenses % of Revenue | B19: 0.145 | C19: 0.14 | D19: 0.14
A20: Tax Rate % | B20: 0.24 | C20: 0.24 | D20: 0.24
A22: Balance sheet Assumptions
A24: ASSUMPTION HEADER | B24: FY2026E | C24: FY2027E | D24: FY2028E
A25: Capex ₹ Cr | B25: 300 | C25: 200 | D25: 150
A26: Debtor Days | B26: 88 | C26: 85 | D26: 82
A27: Inventory Days | B27: 70 | C27: 68 | D27: 65
A28: Payable Days | B28: 42 | C28: 44 | D28: 45
A29: Dividend Payout % | B29: 0.2 | C29: 0.2 | D29: 0.2

Sheet P&L
A1: VINATI ORGANICS — PROFIT & LOSS STATEMENT | K1: COLOR CODING LEGEND
A2: (₹ in Crores) | K2: Color | L2: Meaning
A3: Particulars | B3: FY2020 | C3: FY2021 | D3: FY2022 | E3: FY2023 | F3: FY2024 | G3: FY2025 | H3: FY2026E | I3: FY2027E | J3: FY2028E | K3: Blue fill | L3: Hard coded input (number typed manually
A4: INCOME | K4: Green fill | L4: Formula Cells( calculated by Excel)
A5: Revenue from Operations | B5: ='Raw Data'!B4 -> 1028.87 | C5: ='Raw Data'!C4 -> 954.26 | D5: ='Raw Data'!D4 -> 1615.51 | E5: ='Raw Data'!E4 -> 2072.7 | F5: ='Raw Data'!F4 -> 1900 | G5: ='Raw Data'!G4 -> 2248.1 | H5: =G5*(1+'Assumption '!B13) -> 2517.872 | I5: =H5*(1+'Assumption '!C13) -> 2769.6592 | J5: =I5*(1+'Assumption '!D13) -> 3046.6251 | K5: Yellow fill | L5: Assumption (Inputs in Assumptions tab)
A6: YoY Growth % | H6: =ROUND((H5-G5)/G5*100,1) -> 12 | I6: =ROUND((I5-H5)/H5*100,1) -> 10 | J6: =ROUND((J5-I5)/I5*100,1) -> 10 | K6: Purple fill | L6: Linked from another sheet (pull data across sheets)
A7: Other Income | B7: ='Raw Data'!B5 -> 44.99 | C7: ='Raw Data'!C5 -> 25.86 | D7: ='Raw Data'!D5 -> 60.96 | E7: ='Raw Data'!E5 -> 52.4 | F7: ='Raw Data'!F5 -> 38.8 | G7: ='Raw Data'!G5 -> 44.29 | H7: ='Assumption '!B14 -> 46 | I7: ='Assumption '!C14 -> 48 | J7: ='Assumption '!D14 -> 50
A8: TOTAL INCOME | B8: =B5+B7 -> 1073.86 | C8: =C5+C7 -> 980.12 | D8: =D5+D7 -> 1676.47 | E8: =E5+E7 -> 2125.1 | F8: =F5+F7 -> 1938.8 | G8: =G5+G7 -> 2292.39 | H8: =H5+H7 -> 2563.872 | I8: =I5+I7 -> 2817.6592 | J8: =J5+J7 -> 3096.6251
A10: EXPENSES
A11: Cost of Materials Consumed | B11: ='Raw Data'!B9 -> 0 | C11: ='Raw Data'!C9 -> 0 | D11: ='Raw Data'!D9 -> 0 | E11: ='Raw Data'!E9 -> 1077.9 | F11: ='Raw Data'!F9 -> 1010.2 | G11: ='Raw Data'!G9 -> 1182.29 | H11: =H5*'Assumption '!B15 -> 1309.2934 | I11: =I5*'Assumption '!C15 -> 1440.2228 | J11: =J5*'Assumption '!D15 -> 1553.7788
A12: Purchase of Stock in Trade | E12: ='Raw Data'!E10 -> 0.6 | F12: ='Raw Data'!F10 -> 0 | G12: ='Raw Data'!G10 -> 0
A13: Changes in Inventories | E13: ='Raw Data'!E11 -> -4 | F13: ='Raw Data'!F11 -> 1.1 | G13: ='Raw Data'!G11 -> 14.08
A14: Employee Benefits Expense | B14: ='Raw Data'!B12 -> 0 | C14: ='Raw Data'!C12 -> 0 | D14: ='Raw Data'!D12 -> 0 | E14: ='Raw Data'!E12 -> 99.6 | F14: ='Raw Data'!F12 -> 118.9 | G14: ='Raw Data'!G12 -> 137.99 | H14: =H5*'Assumption '!B16 -> 156.10806 | I14: =I5*'Assumption '!C16 -> 180.02785 | J14: =J5*'Assumption '!D16 -> 198.03063
A15: Finance Costs | B15: ='Raw Data'!B13 -> 2.04 | C15: ='Raw Data'!C13 -> 0.95 | D15: ='Raw Data'!D13 -> 1.65 | E15: ='Raw Data'!E13 -> 1.4 | F15: ='Raw Data'!F13 -> 3.6 | G15: ='Raw Data'!G13 -> 0.52 | H15: ='Assumption '!B17 -> 2 | I15: ='Assumption '!C17 -> 2 | J15: ='Assumption '!D17 -> 2
A16: Depreciation and Amortisation | B16: ='Raw Data'!B14 -> 33.16 | C16: ='Raw Data'!C14 -> 42.91 | D16: ='Raw Data'!D14 -> 45.49 | E16: ='Raw Data'!E14 -> 59 | F16: ='Raw Data'!F14 -> 72.8 | G16: ='Raw Data'!G14 -> 80.75 | H16: ='Assumption '!B18 -> 95 | I16: ='Assumption '!C18 -> 105 | J16: ='Assumption '!D18 -> 112
A17: Other Expenses | B17: ='Raw Data'!B15 -> 0 | C17: ='Raw Data'!C15 -> 0 | D17: ='Raw Data'!D15 -> 0 | E17: ='Raw Data'!E15 -> 327.4 | F17: ='Raw Data'!F15 -> 299.6 | G17: ='Raw Data'!G15 -> 328.53 | H17: =H5*'Assumption '!B19 -> 365.09144 | I17: =I5*'Assumption '!C19 -> 387.75229 | J17: =J5*'Assumption '!D19 -> 426.52752
A18: TOTAL EXPENSES | B18: =SUM(B11:B17) -> 35.2 | C18: =SUM(C11:C17) -> 43.86 | D18: =SUM(D11:D17) -> 47.14 | E18: =SUM(E11:E17) -> 1561.9 | F18: =SUM(F11:F17) -> 1506.2 | G18: =SUM(G11:G17) -> 1744.16 | H18: =SUM(H11:H17) -> 1927.4929 | I18: =SUM(I11:I17) -> 2115.0029 | J18: =SUM(J11:J17) -> 2292.337
A20: Profit Before Tax | B20: ='Raw Data'!B17 -> 1038.66 | C20: ='Raw Data'!C17 -> 936.26 | D20: ='Raw Data'!D17 -> 1629.33 | E20: ='Raw Data'!E17 -> 563.2 | F20: ='Raw Data'!F17 -> 432.5 | G20: =G8-G18 -> 548.23 | H20: =H8-H18 -> 636.37906 | I20: =I8-I18 -> 702.65628 | J20: =J8-J18 -> 804.28816
A21: Tax Expense | B21: ='Raw Data'!B18 -> 90.84 | C21: ='Raw Data'!C18 -> 65.91 | D21: ='Raw Data'!D18 -> 102.63 | E21: ='Raw Data'!E18 -> 144 | F21: ='Raw Data'!F18 -> 109.1 | G21: ='Raw Data'!G18 -> 133 | H21: =H20*'Assumption '!B20 -> 152.73097 | I21: =I20*'Assumption '!C20 -> 168.63751 | J21: =J20*'Assumption '!D20 -> 193.02916
A22: NET PROFIT (PAT) | B22: =B20-B21 -> 947.82 | C22: =C20-C21 -> 870.35 | D22: =D20-D21 -> 1526.7 | E22: =E20-E21 -> 419.2 | F22: =F20-F21 -> 323.4 | G22: =G20-G21 -> 415.23 | H22: =H20-H21 -> 483.64808 | I22: =I20-I21 -> 534.01877 | J22: =J20-J21 -> 611.259
A24: KEY METRICS
A25: EBITDA | B25: =B20+B16+B15 -> 1073.86 | C25: =C20+C16+C15 -> 980.12 | D25: =D20+D16+D15 -> 1676.47 | E25: =E20+E16+E15 -> 623.6 | F25: =F20+F16+F15 -> 508.9 | G25: =G20+G16+G15 -> 629.5 | H25: =H20+H16+H15 -> 733.37906 | I25: =I20+I16+I15 -> 809.65628 | J25: =J20+J16+J15 -> 918.28816
A26: EBITDA Margin % | B26: ='Raw Data'!B23 -> 104.4 | C26: ='Raw Data'!C23 -> 102.7 | D26: ='Raw Data'!D23 -> 103.8 | E26: ='Raw Data'!E23 -> 30.1 | F26: ='Raw Data'!F23 -> 26.8 | G26: ='Raw Data'!G23 -> 28 | H26: =ROUND(H25/H5*100,1) -> 29.1 | I26: =ROUND(I25/I5*100,1) -> 29.2 | J26: =ROUND(J25/J5*100,1) -> 30.1
A27: Net Profit Margin % | B27: ='Raw Data'!B24 -> 92.1 | C27: ='Raw Data'!C24 -> 91.2 | D27: ='Raw Data'!D24 -> 94.5 | E27: ='Raw Data'!E24 -> 20.2 | F27: ='Raw Data'!F24 -> 17 | G27: ='Raw Data'!G24 -> 18.5 | H27: =ROUND(H22/H5*100,1) -> 19.2 | I27: =ROUND(I22/I5*100,1) -> 19.3 | J27: =ROUND(J22/J5*100,1) -> 20.1
A28: EPS - Basic | B28: ='Raw Data'!B25 -> 32.47 | C28: ='Raw Data'!C25 -> 26.2 | D28: ='Raw Data'!D25 -> 33.72 | E28: ='Raw Data'!E25 -> 40.43 | F28: ='Raw Data'!F25 -> 31.2 | G28: ='Raw Data'!G25 -> 40.05 | H28: =H22/10.37 -> 46.639159 | I28: =I22/10.37 -> 51.496507 | J28: =J22/10.37 -> 58.944937

Sheet Balance sheet
A1: VINATI ORGANICS — BALANCE SHEET
A2: (₹ in Crores)
A4: Particulars | B4: FY2020 | C4: FY2021 | D4: FY2022 | E4: FY2023 | F4: FY2024 | G4: FY2025 | H4: FY2026E | I4: FY2027E | J4: FY2028E
A5: ASSETS
A6: NON-CURRENT ASSETS | L6: COLOR CODING LEGEND
A7: Property Plant & Equipment | E7: 1157.79 | F7: 1328.9 | G7: 1381.47 | H7: =G7+'Assumption '!B25-'P&L'!H16 -> 1586.47 | I7: =H7+'Assumption '!C25-'P&L'!I16 -> 1681.47 | J7: =I7+'Assumption '!D25-'P&L'!J16 -> 1719.47 | L7: Color | M7: Meaning
A8: Capital Work in Progress | E8: 229 | F8: 246.1 | G8: 298.48 | H8: 298.48 | I8: 298.48 | J8: 298.48 | L8: Blue fill | M8: Hard coded input (number typed manually
A9: Intangible Assets | E9: 1 | F9: 0.7 | G9: 0.44 | H9: 0.44 | I9: 0.44 | J9: 0.44 | L9: Green fill | M9: Formula Cells( calculated by Excel)
A10: Investments - Non Current | E10: 61.5 | F10: 212.4 | G10: 513.25 | H10: 513.25 | I10: 513.25 | J10: 513.25 | L10: Yellow fill | M10: Assumption (Inputs in Assumptions tab)
A11: Other Financial Assets — NC | E11: 0.9 | F11: 29.4 | G11: 62.21 | H11: 62.21 | I11: 62.21 | J11: 62.21
A12: Other Non-Current Assets | E12: 72 | F12: 40.4 | G12: 38.37 | H12: 38.37 | I12: 38.37 | J12: 38.37 | L12: Purple fill | M12: Linked from another sheet (pull data across sheets)
A13: TOTAL NON-CURRENT ASSETS | E13: =SUM(E7:E12) -> 1522.19 | F13: =SUM(F7:F12) -> 1857.9 | G13: =SUM(G7:G12) -> 2294.22 | H13: =SUM(H7:H12) -> 2499.22 | I13: =SUM(I7:I12) -> 2594.22 | J13: =SUM(J7:J12) -> 2632.22
A15: CURRENT ASSETS
A16: Inventories | E16: 233 | F16: 198.4 | G16: 216.78 | H16: ='P&L'!H11*'Assumption '!B27/365 -> 251.09737 | I16: ='P&L'!I11*'Assumption '!C27/365 -> 268.31548 | J16: ='P&L'!J11*'Assumption '!D27/365 -> 276.70034
A17: Investments | E17: 193.9 | F17: 24.9 | G17: 10 | H17: 10 | I17: 10 | J17: 10
A18: Trade Receivables | E18: 463.8 | F18: 530.5 | G18: 593.74 | H18: ='P&L'!H5*'Assumption '!B26/365 -> 607.04859 | I18: ='P&L'!I5*'Assumption '!C26/365 -> 644.98913 | J18: ='P&L'!J5*'Assumption '!D26/365 -> 684.44729
A19: Bank Balances other than Cash | E19: 7.3 | F19: 12.4 | G19: 3.44 | H19: 0.07 | I19: 0.07 | J19: 0.07
A20: Cash & Cash Equivalents | E20: 2.3 | F20: 0.3 | G20: 0.07 | H20: ='cash flow'!E42 -> 138.23093 | I20: ='cash flow'!F42 -> 436.60478 | J20: ='cash flow'!G42 -> 857.07483
A21: Loans | E21: 0 | F21: 0.1 | G21: 0.1 | H21: 0.1 | I21: 0.1 | J21: 0.1
A22: Current Tax Assets | E22: 27.4 | F22: 38.5 | G22: 45.94 | H22: 45.94 | I22: 45.94 | J22: 45.94
A23: Other Financial Assets | E23: 3 | F23: 23 | G23: 11.13 | H23: 11.13 | I23: 11.13 | J23: 11.13
A24: Other Current Assets | E24: 130.5 | F24: 141.4 | G24: 87.55 | H24: 87.55 | I24: 87.55 | J24: 87.55
A25: TOTAL CURRENT ASSETS | E25: =SUM(E16:E24) -> 1061.2 | F25: =SUM(F16:F24) -> 969.5 | G25: =SUM(G16:G24) -> 968.75 | H25: =SUM(H16:H24) -> 1151.1669 | I25: =SUM(I16:I24) -> 1504.6994 | J25: =SUM(J16:J24) -> 1973.0125
A27: TOTAL ASSETS | E27: =E13+E25 -> 2583.39 | F27: =F13+F25 -> 2827.4 | G27: =G13+G25 -> 3262.97 | H27: =H13+H25 -> 3650.3869 | I27: =I13+I25 -> 4098.9194 | J27: =J13+J25 -> 4605.2325
A29: EQUITY & LIABILITIES
A30: EQUITY
A31: Share Capital | E31: 10.3 | F31: 10.4 | G31: 10.37 | H31: 10.37 | I31: 10.37 | J31: 10.37
A32: Other Equity | E32: 2203.5 | F32: 2454 | G32: 2796.36 | H32: =G32+'P&L'!H22-('P&L'!H22*'Assumption '!B29) -> 3183.2785 | I32: =H32+'P&L'!I22-('P&L'!I22*'Assumption '!C29) -> 3610.4935 | J32: =I32+'P&L'!J22-('P&L'!J22*'Assumption '!D29) -> 4099.5007
A33: TOTAL EQUITY | E33: =SUM(E31:E32) -> 2213.8 | F33: =SUM(F31:F32) -> 2464.4 | G33: =G31+G32 -> 2806.73 | H33: =H31+H32 -> 3193.6485 | I33: =I31+I32 -> 3620.8635 | J33: =J31+J32 -> 4109.8707
A35: NON-CURRENT LIABILITIES
A36: Deferred Tax Liabilities | E36: 110 | F36: 133.5 | G36: 154.04 | H36: 168 | I36: 180 | J36: 191
A37: Other Financial Liabilities | E37: 6.9 | F37: 1.7 | G37: 7.04 | H37: 7.04 | I37: 7.04 | J37: 7.04
A38: Borrowings | E38: 10.4 | F38: 6.8 | G38: 0 | H38: 0 | I38: 0 | J38: 0
A39: Other Non-Current Liabilities | E39: 0 | F39: 17.1 | G39: 0 | H39: 0 | I39: 0 | J39: 0
A40: TOTAL NON-CURRENT LIABILITIES | E40: =SUM(E36:E39) -> 127.3 | F40: =SUM(F36:F39) -> 159.1 | G40: =SUM(G36:G39) -> 161.08 | H40: =SUM(H36:H39) -> 175.04 | I40: =SUM(I36:I39) -> 187.04 | J40: =SUM(J36:J39) -> 198.04
A42: CURRENT LIABILITIES
A43: Borrowings | E43: 24.9 | F43: 4.6 | G43: 62.62 | H43: 40 | I43: 20 | J43: 0
A44: Other Financial Liabilities | E44: 9.6 | F44: 12.6 | G44: 19.66 | H44: 19.66 | I44: 19.66 | J44: 19.66
A45: Provisions | E45: 6 | F45: 7.7 | G45: 9.24 | H45: 9.24 | I45: 9.24 | J45: 9.24
A46: Trade Payables | E46: 119.8 | F46: 100.7 | G46: 142.53 | H46: ='P&L'!H11*'Assumption '!B28/365 -> 150.65842 | I46: ='P&L'!I11*'Assumption '!C28/365 -> 173.6159 | J46: ='P&L'!J11*'Assumption '!D28/365 -> 191.56177
...

Sheet cash flow
A1: VINATI ORGANICS — CASH FLOW STATEMENT | N1: COLOR CODING LEGEND
A2: (₹ in Crores) | N2: Color | O2: Meaning
A3: PARTICULAR | B3: FY2023 | C3: FY2024 | D3: FY2025 | E3: FY2026E | F3: FY2027E | G3: FY2028E | N3: Blue fill | O3: Hard coded input (number typed manually
A4: OPERATING ACTIVITIES | N4: Green fill | O4: Formula Cells( calculated by Excel)
A5: Profit Before Tax | C5: 432.47 | D5: 548.23 | E5: ='P&L'!H20 -> 636.37906 | F5: ='P&L'!I20 -> 702.65628 | G5: ='P&L'!J20 -> 804.28816 | N5: Yellow fill | O5: Assumption (Inputs in Assumptions tab)
A6: Add: Depreciation | C6: 72.79 | D6: 80.75 | E6: ='P&L'!H16 -> 95 | F6: ='P&L'!I16 -> 105 | G6: ='P&L'!J16 -> 112 | N6: Purple fill | O6: Linked from another sheet (pull data across sheets)
A7: Add: Finance Costs | C7: 3.62 | D7: 0.52 | E7: ='P&L'!H15 -> 2 | F7: ='P&L'!I15 -> 2 | G7: ='P&L'!J15 -> 2
A8: Other Adjustments (net) | C8: -14.15 | D8: -14.64 | E8: -14.64 | F8: -14.64 | G8: -14.64
A9: Operating Profit Before Working Capital Changes | C9: 493.73 | D9: 614.86 | E9: =SUM(E5:E8) -> 718.73906 | F9: =SUM(F5:F8) -> 795.01628 | G9: =SUM(G5:G8) -> 903.64816
A11: Working Capital Changes
A12: (Increase)/Decrease in Inventories | C12: 34.58 | D12: -18.35 | E12: =-('Balance sheet'!H16-'Balance sheet'!G16) -> -34.317372 | F12: =-('Balance sheet'!I16-'Balance sheet'!H16) -> -17.218106 | G12: =-('Balance sheet'!J16-'Balance sheet'!I16) -> -8.3848587
A13: (Increase)/Decrease in Trade Receivables | C13: -60.96 | D13: -62.61 | E13: =-('Balance sheet'!H18-'Balance sheet'!G18) -> -13.308592 | F13: =-('Balance sheet'!I18-'Balance sheet'!H18) -> -37.940537 | G13: =-('Balance sheet'!J18-'Balance sheet'!I18) -> -39.458158
A14: (Increase)/Decrease in Other Current Assets | C14: 0
A15: Increase/(Decrease) in Trade Payables | C15: -20.71 | D15: 41.48 | E15: ='Balance sheet'!H46-'Balance sheet'!G46 -> 8.1284232 | F15: ='Balance sheet'!I46-'Balance sheet'!H46 -> 22.957474 | G15: ='Balance sheet'!J46-'Balance sheet'!I46 -> 17.945874
A16: Increase/(Decrease) in Other Current Liabilities | C16: -21.34 | D16: 13.38 | E16: ='Balance sheet'!H48-'Balance sheet'!G48 -> 0 | F16: ='Balance sheet'!I48-'Balance sheet'!H48 -> 0 | G16: ='Balance sheet'!J48-'Balance sheet'!I48 -> 0
A17: Change in Other Items (net)
A18: Total Working Capital Changes | C18: =SUM(C12:C16) -> -68.43 | D18: =SUM(D12:D16) -> -26.1 | E18: =SUM(E12:E16) -> -39.497541 | F18: =SUM(F12:F16) -> -32.201168 | G18: =SUM(G12:G16) -> -29.897143
A20: Cash Generated From Operations | C20: 425.31 | D20: 588.76 | E20: =E9+E18 -> 679.24152 | F20: =F9+F18 -> 762.81511 | G20: =G9+G18 -> 873.75102
A21: Less: Tax Paid | C21: -87.14 | D21: -94.32 | E21: =-'P&L'!H21 -> -152.73097 | F21: =-'P&L'!I21 -> -168.63751 | G21: =-'P&L'!J21 -> -193.02916
A22: NET CASH FROM OPERATING ACTIVITIES | C22: 338.17 | D22: 494.44 | E22: =E20+E21 -> 526.51054 | F22: =F20+F21 -> 594.1776 | G22: =G20+G21 -> 680.72186
A24: INVESTING ACTIVITIES
A25: Purchase of Fixed Assets (Capex) | C25: -230.34 | D25: -189.73 | E25: =-'Assumption '!B25 -> -300 | F25: =-'Assumption '!C25 -> -200 | G25: =-'Assumption '!D25 -> -150
A26: Investment in Subsidiary | C26: -172.54 | D26: -348.12 | E26: 0 | F26: 0 | G26: 0
A27: Proceeds from sale of PPE | C27: 0.89 | D27: 3.18 | E27: 3 | F27: 2 | G27: 2
A28: Purchase of Investments | C28: -62.4 | D28: 0 | E28: 0 | F28: 0 | G28: 0
A29: Proceeds from Investments | C29: 107.27 | D29: 30.08 | E29: 15 | F29: 15 | G29: 15
A30: Interest Income | C30: 8.86 | D30: 14.86 | E30: 15 | F30: 16 | G30: 17
A31: Other Investing Items | C31: -5.38 | D31: 9.94 | E31: 0 | F31: 0 | G31: 0
A32: NET CASH FROM INVESTING ACTIVITIES | C32: -353.4 | D32: -479.74 | E32: =SUM(E25:E31) -> -267 | F32: =SUM(F25:F31) -> -167 | G32: =SUM(G25:G31) -> -116
A34: FINANCING ACTIVITIES
A35: Proceeds from/(Repayment of) Borrowings | C35: -30.57 | D35: 57.97 | E35: ='Balance sheet'!H43-'Balance sheet'!G43 -> -22.62 | F35: ='Balance sheet'!I43-'Balance sheet'!H43 -> -20 | G35: ='Balance sheet'!J43-'Balance sheet'!I43 -> -20
A36: Dividends Paid | C36: -72.25 | D36: -72.43 | E36: =-('P&L'!H22*'Assumption '!B29) -> -96.729617 | F36: =-('P&L'!I22*'Assumption '!C29) -> -106.80375 | G36: =-('P&L'!J22*'Assumption '!D29) -> -122.2518
A37: Finance Costs Paid | C37: -3.64 | D37: -0.52 | E37: =-'P&L'!H15 -> -2 | F37: =-'P&L'!I15 -> -2 | G37: =-'P&L'!J15 -> -2
A38: NET CASH FROM FINANCING ACTIVITIES | C38: -106.39 | D38: -14.94 | E38: =SUM(E35:E37) -> -121.34962 | F38: =SUM(F35:F37) -> -128.80375 | G38: =SUM(G35:G37) -> -144.2518
A40: NET CHANGE IN CASH | C40: -121.62 | D40: -0.24 | E40: =E22+E32+E38 -> 138.16093 | F40: =F22+F32+F38 -> 298.37385 | G40: =G22+G32+G38 -> 420.47006
A41: Opening Cash Balance | C41: 121.93 | D41: 0.31 | E41: =D42 -> 0.07 | F41: =E42 -> 138.23093 | G41: =F42 -> 436.60478
A42: CLOSING CASH BALANCE | C42: 0.31 | D42: 0.07 | E42: =E40+E41 -> 138.23093 | F42: =F40+F41 -> 436.60478 | G42: =G40+G41 -> 857.07483

Sheet DCF
A1: VINATI ORGANICS — DCF VALUATION | N1: COLOR CODING LEGEND
A2: (₹ in Crores) | N2: Color | O2: Meaning
N3: Blue fill | O3: Hard coded input (number typed manually
A4: WACC ASSUMPTIONS | N4: Green fill | O4: Formula Cells( calculated by Excel)
A5: Risk Free Rate | B5: 0.07 | N5: Yellow fill | O5: Assumption (Inputs in Assumptions tab)
A6: Equity Risk Premium | B6: 0.055 | N6: Purple fill | O6: Linked from another sheet (pull data across sheets)
A7: Beta | B7: 0.85
A8: Cost of Equity | B8: =B5+(B6*B7) -> 0.11675
A9: Cost of Debt (Pre Tax) | B9: 0.08
A10: Tax Rate | B10: 0.24
A11: After Tax Cost of Debt | B11: =B9*(1-B10) -> 0.0608
A12: Debt Weight | B12: 0.005
A13: Equity Weight | B13: 0.995
A14: WACC | B14: =(B13*B8)+(B12*B11) -> 0.11647025
A17: FCF CALCULATION | B17: FY2026E | C17: FY2027E | D17: FY2028E
A18: EBIT | B18: ='P&L'!H20+'P&L'!H15 -> 638.37906 | C18: ='P&L'!I20+'P&L'!I15 -> 704.65628 | D18: ='P&L'!J20+'P&L'!J15 -> 806.28816
A19: Tax on EBIT | B19: =B18*B10 -> 153.21097 | C19: =C18*B10 -> 169.11751 | D19: =D18*B10 -> 193.50916
A20: NOPAT | B20: =B18-B19 -> 485.16808 | C20: =C18-C19 -> 535.53877 | D20: =D18-D19 -> 612.779
A21: Add Depreciation | B21: ='P&L'!H16 -> 95 | C21: ='P&L'!I16 -> 105 | D21: ='P&L'!J16 -> 112
A22: Less Capex | B22: ='Assumption '!B25 -> 300 | C22: ='Assumption '!C25 -> 200 | D22: ='Assumption '!D25 -> 150
A23: Less Change in Working Capital | B23: ='cash flow'!E18 -> -39.497541 | C23: ='cash flow'!F18 -> -32.201168 | D23: ='cash flow'!G18 -> -29.897143
A24: Free Cash Flow to Firm | B24: =B20+B21-B22-B23 -> 319.66562 | C24: =C20+C21-C22-C23 -> 472.73994 | D24: =D20+D21-D22-D23 -> 604.67614
A25: Year Number | B25: 1 | C25: 2 | D25: 3
A26: Discount Factor | B26: =1/((1+$B$14)^B25) -> 0.89567993 | C26: =1/((1+$B$14)^C25) -> 0.80224254 | D26: =1/((1+$B$14)^D25) -> 0.71855255
A27: PV of FCF | B27: =B24*B26 -> 286.31808 | C27: =C24*C26 -> 379.25209 | D27: =D24*D26 -> 434.49158
A29: VALUATION
A30: Terminal Growth Rate | B30: 0.05
A31: Terminal Value | B31: =D24*(1+B30)/(B14-B30) -> 9551.7912
A32: PV of Terminal Value | B32: =B31/((1+B14)^3) -> 6863.4639
A33: Sum of PV of FCFs | B33: =SUM(B27:D27) -> 1100.0618
A34: Enterprise Value | B34: =B32+B33 -> 7963.5257
A35: Less Total Debt | B35: ='Balance sheet'!G43+'Balance sheet'!G38 -> 62.62
A36: Add Cash & Investments | B36: ='Balance sheet'!G20+'Balance sheet'!G17 -> 10.07
A37: Equity Value | B37: =B34-B35+B36 -> 7910.9757
A38: Shares Outstanding (Crores) | B38: 10.37
A39: Intrinsic Value Per Share (₹) | B39: =B37/B38 -> 762.87133
A40: Current Market Price (₹) | B40: 1312
A41: Upside / Downside % | B41: =(B39-B40)/B40*100 -> -41.854319
A42: Recommendation | B42: =IF(B41>15,"BUY",IF(B41<-15,"AVOID","HOLD")) -> AVOID
